INFO:root:(4 points) os.path.isfile("lab5.py") is True
INFO:root:(2 points) m.simulate_grades(2,[5,5,5]).shape == (2,3) is True
INFO:root:Executed gd = m.simulate_grades(10, [5, 20, 40])
INFO:root:(2 points) gd[:,0].max() < 5 is True
INFO:root:(2 points) gd[:,1].max() < 20 is True
INFO:root:(2 points) gd[:,2].max() < 40 is True
INFO:root:(2 points) m.simulate_grade_df(3,{"M":5,"HW":5}).shape == (3,2) is True
INFO:root:Executed a = m.GradeBook(array([[5,5],[1,1]]),['22','34'],['F','M'],[10, 10])
INFO:root:(2 points) type(a.raw_grades) == DataFrame is True
INFO:root:(2 points) a.total_grades is None
INFO:root:(2 points) a.raw_grades.shape == (2,2) is True
INFO:root:(2 points) a.raw_grades.ix[0,0] is 5
INFO:root:(2 points) a.max_scores[0] is 10
INFO:root:Executed b = a.compute_total_grades([0.3, 0.7], 100)
ERROR:root:Got exception on main handler
Traceback (most recent call last):
  File "/home/grader/grade/133/deadmau/check.py", line 54, in run
    exec(command, g)
  File "<string>", line 1, in <module>
  File "/home/grader/grade/133/deadmau/lab5.py", line 188, in compute_total_grades
    ave = [sum(weight.loc[row]) for row in weight.index.values]
  File "/usr/lib64/python2.7/site-packages/pandas/core/frame.py", line 2015, in __getattr__
    (type(self).__name__, name))
AttributeError: 'DataFrame' object has no attribute 'loc'
ERROR:root:Traceback (most recent call last):
  File "/home/grader/grade/133/deadmau/check.py", line 54, in run
    exec(command, g)
  File "<string>", line 1, in <module>
  File "/home/grader/grade/133/deadmau/lab5.py", line 188, in compute_total_grades
    ave = [sum(weight.loc[row]) for row in weight.index.values]
  File "/usr/lib64/python2.7/site-packages/pandas/core/frame.py", line 2015, in __getattr__
    (type(self).__name__, name))
AttributeError: 'DataFrame' object has no attribute 'loc'
Traceback (most recent call last):
  File "/home/grader/grade/133/deadmau/check.py", line 54, in run
    exec(command, g)
  File "<string>", line 1, in <module>
  File "/home/grader/grade/133/deadmau/lab5.py", line 188, in compute_total_grades
    ave = [sum(weight.loc[row]) for row in weight.index.values]
  File "/usr/lib64/python2.7/site-packages/pandas/core/frame.py", line 2015, in __getattr__
    (type(self).__name__, name))
AttributeError: 'DataFrame' object has no attribute 'loc'
ERROR:root:(2 points) Checking len(b)
ERROR:root:... Expecting: 8
ERROR:root:... But got:   Traceback error
ERROR:root:Got exception:
Traceback (most recent call last):
  File "/home/grader/grade/133/deadmau/check.py", line 70, in check
    result = eval(command, g)
  File "<string>", line 1, in <module>
NameError: name 'b' is not defined
ERROR:root:Traceback (most recent call last):
  File "/home/grader/grade/133/deadmau/check.py", line 70, in check
    result = eval(command, g)
  File "<string>", line 1, in <module>
NameError: name 'b' is not defined
Traceback (most recent call last):
  File "/home/grader/grade/133/deadmau/check.py", line 70, in check
    result = eval(command, g)
  File "<string>", line 1, in <module>
NameError: name 'b' is not defined
ERROR:root:(2 points) Checking a.total_grades["22"]
ERROR:root:... Expecting: 50
ERROR:root:... But got:   Traceback error
ERROR:root:Got exception:
Traceback (most recent call last):
  File "/home/grader/grade/133/deadmau/check.py", line 70, in check
    result = eval(command, g)
  File "<string>", line 1, in <module>
TypeError: 'NoneType' object has no attribute '__getitem__'
ERROR:root:Traceback (most recent call last):
  File "/home/grader/grade/133/deadmau/check.py", line 70, in check
    result = eval(command, g)
  File "<string>", line 1, in <module>
TypeError: 'NoneType' object has no attribute '__getitem__'
Traceback (most recent call last):
  File "/home/grader/grade/133/deadmau/check.py", line 70, in check
    result = eval(command, g)
  File "<string>", line 1, in <module>
TypeError: 'NoneType' object has no attribute '__getitem__'
ERROR:root:(2 points) Checking a.total_grades["34"]
ERROR:root:... Expecting: 10
ERROR:root:... But got:   Traceback error
ERROR:root:Got exception:
Traceback (most recent call last):
  File "/home/grader/grade/133/deadmau/check.py", line 70, in check
    result = eval(command, g)
  File "<string>", line 1, in <module>
TypeError: 'NoneType' object has no attribute '__getitem__'
ERROR:root:Traceback (most recent call last):
  File "/home/grader/grade/133/deadmau/check.py", line 70, in check
    result = eval(command, g)
  File "<string>", line 1, in <module>
TypeError: 'NoneType' object has no attribute '__getitem__'
Traceback (most recent call last):
  File "/home/grader/grade/133/deadmau/check.py", line 70, in check
    result = eval(command, g)
  File "<string>", line 1, in <module>
TypeError: 'NoneType' object has no attribute '__getitem__'
INFO:root:You got a 24 out of 30.
